<?xml version="1.0" encoding="UTF-8"?>
<testng-results skipped="0" failed="4" ignored="0" total="5" passed="1">
  <reporter-output>
  </reporter-output>
  <suite name="Failed suite [Suite]" duration-ms="31796" started-at="2021-07-17T03:59:56Z" finished-at="2021-07-17T04:00:28Z">
    <groups>
    </groups>
    <test name="Test(failed)" duration-ms="31796" started-at="2021-07-17T03:59:56Z" finished-at="2021-07-17T04:00:28Z">
      <class name="com.swap.TestCases.TC_LoginTest_001">
        <test-method status="PASS" signature="setUp(java.lang.String)[pri:0, instance:com.swap.TestCases.TC_LoginTest_001@dc24521]" name="setUp" is-config="true" duration-ms="9078" started-at="2021-07-17T03:59:57Z" finished-at="2021-07-17T04:00:06Z">
          <params>
            <param index="0">
              <value>
                <![CDATA[chrome]]>
              </value>
            </param>
          </params>
          <reporter-output>
          </reporter-output>
        </test-method> <!-- setUp -->
        <test-method status="PASS" signature="loginTest()[pri:0, instance:com.swap.TestCases.TC_LoginTest_001@dc24521]" name="loginTest" duration-ms="2641" started-at="2021-07-17T04:00:06Z" finished-at="2021-07-17T04:00:08Z">
          <reporter-output>
          </reporter-output>
        </test-method> <!-- loginTest -->
        <test-method status="PASS" signature="tearDown()[pri:0, instance:com.swap.TestCases.TC_LoginTest_001@dc24521]" name="tearDown" is-config="true" duration-ms="1102" started-at="2021-07-17T04:00:08Z" finished-at="2021-07-17T04:00:10Z">
          <reporter-output>
          </reporter-output>
        </test-method> <!-- tearDown -->
      </class> <!-- com.swap.TestCases.TC_LoginTest_001 -->
      <class name="com.swap.TestCases.TC_LoginDDT_002">
        <test-method status="PASS" signature="setUp(java.lang.String)[pri:0, instance:com.swap.TestCases.TC_LoginDDT_002@10bdf5e5]" name="setUp" is-config="true" duration-ms="5570" started-at="2021-07-17T04:00:10Z" finished-at="2021-07-17T04:00:15Z">
          <params>
            <param index="0">
              <value>
                <![CDATA[chrome]]>
              </value>
            </param>
          </params>
          <reporter-output>
          </reporter-output>
        </test-method> <!-- setUp -->
        <test-method status="FAIL" signature="loginDDT(java.lang.String, java.lang.String)[pri:0, instance:com.swap.TestCases.TC_LoginDDT_002@10bdf5e5]" name="loginDDT" duration-ms="3186" started-at="2021-07-17T04:00:17Z" data-provider="LoginData" finished-at="2021-07-17T04:00:20Z">
          <params>
            <param index="0">
              <value>
                <![CDATA[mngr83460]]>
              </value>
            </param>
            <param index="1">
              <value>
                <![CDATA[qABUzyj]]>
              </value>
            </param>
          </params>
          <exception class="java.lang.AssertionError">
            <message>
              <![CDATA[The following asserts failed:
expected [true] but found [false]]]>
            </message>
            <full-stacktrace>
              <![CDATA[java.lang.AssertionError: The following asserts failed:
expected [true] but found [false]
at org.testng.asserts.SoftAssert.assertAll(SoftAssert.java:43)
at com.swap.TestCases.TC_LoginDDT_002.loginDDT(TC_LoginDDT_002.java:46)
at sun.reflect.NativeMethodAccessorImpl.invoke0(Native Method)
at sun.reflect.NativeMethodAccessorImpl.invoke(NativeMethodAccessorImpl.java:62)
at sun.reflect.DelegatingMethodAccessorImpl.invoke(DelegatingMethodAccessorImpl.java:43)
at java.lang.reflect.Method.invoke(Method.java:498)
at org.testng.internal.MethodInvocationHelper.invokeMethod(MethodInvocationHelper.java:124)
at org.testng.internal.Invoker.invokeMethod(Invoker.java:583)
at org.testng.internal.Invoker.invokeTestMethod(Invoker.java:719)
at org.testng.internal.Invoker.invokeTestMethods(Invoker.java:989)
at org.testng.internal.TestMethodWorker.invokeTestMethods(TestMethodWorker.java:125)
at org.testng.internal.TestMethodWorker.run(TestMethodWorker.java:109)
at org.testng.TestRunner.privateRun(TestRunner.java:648)
at org.testng.TestRunner.run(TestRunner.java:505)
at org.testng.SuiteRunner.runTest(SuiteRunner.java:455)
at org.testng.SuiteRunner.runSequentially(SuiteRunner.java:450)
at org.testng.SuiteRunner.privateRun(SuiteRunner.java:415)
at org.testng.SuiteRunner.run(SuiteRunner.java:364)
at org.testng.SuiteRunnerWorker.runSuite(SuiteRunnerWorker.java:52)
at org.testng.SuiteRunnerWorker.run(SuiteRunnerWorker.java:84)
at org.testng.TestNG.runSuitesSequentially(TestNG.java:1208)
at org.testng.TestNG.runSuitesLocally(TestNG.java:1137)
at org.testng.TestNG.runSuites(TestNG.java:1049)
at org.testng.TestNG.run(TestNG.java:1017)
at org.testng.remote.AbstractRemoteTestNG.run(AbstractRemoteTestNG.java:115)
at org.testng.remote.RemoteTestNG.initAndRun(RemoteTestNG.java:251)
at org.testng.remote.RemoteTestNG.main(RemoteTestNG.java:77)
]]>
            </full-stacktrace>
          </exception> <!-- java.lang.AssertionError -->
          <reporter-output>
          </reporter-output>
        </test-method> <!-- loginDDT -->
        <test-method status="FAIL" signature="loginDDT(java.lang.String, java.lang.String)[pri:0, instance:com.swap.TestCases.TC_LoginDDT_002@10bdf5e5]" name="loginDDT" duration-ms="2961" started-at="2021-07-17T04:00:20Z" data-provider="LoginData" finished-at="2021-07-17T04:00:23Z">
          <params>
            <param index="0">
              <value>
                <![CDATA[mngr137319]]>
              </value>
            </param>
            <param index="1">
              <value>
                <![CDATA[bAdYvyb]]>
              </value>
            </param>
          </params>
          <exception class="java.lang.AssertionError">
            <message>
              <![CDATA[The following asserts failed:
expected [true] but found [false]]]>
            </message>
            <full-stacktrace>
              <![CDATA[java.lang.AssertionError: The following asserts failed:
expected [true] but found [false]
at org.testng.asserts.SoftAssert.assertAll(SoftAssert.java:43)
at com.swap.TestCases.TC_LoginDDT_002.loginDDT(TC_LoginDDT_002.java:46)
at sun.reflect.NativeMethodAccessorImpl.invoke0(Native Method)
at sun.reflect.NativeMethodAccessorImpl.invoke(NativeMethodAccessorImpl.java:62)
at sun.reflect.DelegatingMethodAccessorImpl.invoke(DelegatingMethodAccessorImpl.java:43)
at java.lang.reflect.Method.invoke(Method.java:498)
at org.testng.internal.MethodInvocationHelper.invokeMethod(MethodInvocationHelper.java:124)
at org.testng.internal.Invoker.invokeMethod(Invoker.java:583)
at org.testng.internal.Invoker.invokeTestMethod(Invoker.java:719)
at org.testng.internal.Invoker.invokeTestMethods(Invoker.java:989)
at org.testng.internal.TestMethodWorker.invokeTestMethods(TestMethodWorker.java:125)
at org.testng.internal.TestMethodWorker.run(TestMethodWorker.java:109)
at org.testng.TestRunner.privateRun(TestRunner.java:648)
at org.testng.TestRunner.run(TestRunner.java:505)
at org.testng.SuiteRunner.runTest(SuiteRunner.java:455)
at org.testng.SuiteRunner.runSequentially(SuiteRunner.java:450)
at org.testng.SuiteRunner.privateRun(SuiteRunner.java:415)
at org.testng.SuiteRunner.run(SuiteRunner.java:364)
at org.testng.SuiteRunnerWorker.runSuite(SuiteRunnerWorker.java:52)
at org.testng.SuiteRunnerWorker.run(SuiteRunnerWorker.java:84)
at org.testng.TestNG.runSuitesSequentially(TestNG.java:1208)
at org.testng.TestNG.runSuitesLocally(TestNG.java:1137)
at org.testng.TestNG.runSuites(TestNG.java:1049)
at org.testng.TestNG.run(TestNG.java:1017)
at org.testng.remote.AbstractRemoteTestNG.run(AbstractRemoteTestNG.java:115)
at org.testng.remote.RemoteTestNG.initAndRun(RemoteTestNG.java:251)
at org.testng.remote.RemoteTestNG.main(RemoteTestNG.java:77)
]]>
            </full-stacktrace>
          </exception> <!-- java.lang.AssertionError -->
          <reporter-output>
          </reporter-output>
        </test-method> <!-- loginDDT -->
        <test-method status="FAIL" signature="loginDDT(java.lang.String, java.lang.String)[pri:0, instance:com.swap.TestCases.TC_LoginDDT_002@10bdf5e5]" name="loginDDT" duration-ms="2264" started-at="2021-07-17T04:00:23Z" data-provider="LoginData" finished-at="2021-07-17T04:00:25Z">
          <params>
            <param index="0">
              <value>
                <![CDATA[mngr83460]]>
              </value>
            </param>
            <param index="1">
              <value>
                <![CDATA[qABUzyz]]>
              </value>
            </param>
          </params>
          <exception class="java.lang.AssertionError">
            <message>
              <![CDATA[The following asserts failed:
expected [true] but found [false]]]>
            </message>
            <full-stacktrace>
              <![CDATA[java.lang.AssertionError: The following asserts failed:
expected [true] but found [false]
at org.testng.asserts.SoftAssert.assertAll(SoftAssert.java:43)
at com.swap.TestCases.TC_LoginDDT_002.loginDDT(TC_LoginDDT_002.java:46)
at sun.reflect.NativeMethodAccessorImpl.invoke0(Native Method)
at sun.reflect.NativeMethodAccessorImpl.invoke(NativeMethodAccessorImpl.java:62)
at sun.reflect.DelegatingMethodAccessorImpl.invoke(DelegatingMethodAccessorImpl.java:43)
at java.lang.reflect.Method.invoke(Method.java:498)
at org.testng.internal.MethodInvocationHelper.invokeMethod(MethodInvocationHelper.java:124)
at org.testng.internal.Invoker.invokeMethod(Invoker.java:583)
at org.testng.internal.Invoker.invokeTestMethod(Invoker.java:719)
at org.testng.internal.Invoker.invokeTestMethods(Invoker.java:989)
at org.testng.internal.TestMethodWorker.invokeTestMethods(TestMethodWorker.java:125)
at org.testng.internal.TestMethodWorker.run(TestMethodWorker.java:109)
at org.testng.TestRunner.privateRun(TestRunner.java:648)
at org.testng.TestRunner.run(TestRunner.java:505)
at org.testng.SuiteRunner.runTest(SuiteRunner.java:455)
at org.testng.SuiteRunner.runSequentially(SuiteRunner.java:450)
at org.testng.SuiteRunner.privateRun(SuiteRunner.java:415)
at org.testng.SuiteRunner.run(SuiteRunner.java:364)
at org.testng.SuiteRunnerWorker.runSuite(SuiteRunnerWorker.java:52)
at org.testng.SuiteRunnerWorker.run(SuiteRunnerWorker.java:84)
at org.testng.TestNG.runSuitesSequentially(TestNG.java:1208)
at org.testng.TestNG.runSuitesLocally(TestNG.java:1137)
at org.testng.TestNG.runSuites(TestNG.java:1049)
at org.testng.TestNG.run(TestNG.java:1017)
at org.testng.remote.AbstractRemoteTestNG.run(AbstractRemoteTestNG.java:115)
at org.testng.remote.RemoteTestNG.initAndRun(RemoteTestNG.java:251)
at org.testng.remote.RemoteTestNG.main(RemoteTestNG.java:77)
]]>
            </full-stacktrace>
          </exception> <!-- java.lang.AssertionError -->
          <reporter-output>
          </reporter-output>
        </test-method> <!-- loginDDT -->
        <test-method status="FAIL" signature="loginDDT(java.lang.String, java.lang.String)[pri:0, instance:com.swap.TestCases.TC_LoginDDT_002@10bdf5e5]" name="loginDDT" duration-ms="2212" started-at="2021-07-17T04:00:25Z" data-provider="LoginData" finished-at="2021-07-17T04:00:27Z">
          <params>
            <param index="0">
              <value>
                <![CDATA[mngr112909]]>
              </value>
            </param>
            <param index="1">
              <value>
                <![CDATA[tytUreg]]>
              </value>
            </param>
          </params>
          <exception class="java.lang.AssertionError">
            <message>
              <![CDATA[The following asserts failed:
expected [true] but found [false]]]>
            </message>
            <full-stacktrace>
              <![CDATA[java.lang.AssertionError: The following asserts failed:
expected [true] but found [false]
at org.testng.asserts.SoftAssert.assertAll(SoftAssert.java:43)
at com.swap.TestCases.TC_LoginDDT_002.loginDDT(TC_LoginDDT_002.java:46)
at sun.reflect.NativeMethodAccessorImpl.invoke0(Native Method)
at sun.reflect.NativeMethodAccessorImpl.invoke(NativeMethodAccessorImpl.java:62)
at sun.reflect.DelegatingMethodAccessorImpl.invoke(DelegatingMethodAccessorImpl.java:43)
at java.lang.reflect.Method.invoke(Method.java:498)
at org.testng.internal.MethodInvocationHelper.invokeMethod(MethodInvocationHelper.java:124)
at org.testng.internal.Invoker.invokeMethod(Invoker.java:583)
at org.testng.internal.Invoker.invokeTestMethod(Invoker.java:719)
at org.testng.internal.Invoker.invokeTestMethods(Invoker.java:989)
at org.testng.internal.TestMethodWorker.invokeTestMethods(TestMethodWorker.java:125)
at org.testng.internal.TestMethodWorker.run(TestMethodWorker.java:109)
at org.testng.TestRunner.privateRun(TestRunner.java:648)
at org.testng.TestRunner.run(TestRunner.java:505)
at org.testng.SuiteRunner.runTest(SuiteRunner.java:455)
at org.testng.SuiteRunner.runSequentially(SuiteRunner.java:450)
at org.testng.SuiteRunner.privateRun(SuiteRunner.java:415)
at org.testng.SuiteRunner.run(SuiteRunner.java:364)
at org.testng.SuiteRunnerWorker.runSuite(SuiteRunnerWorker.java:52)
at org.testng.SuiteRunnerWorker.run(SuiteRunnerWorker.java:84)
at org.testng.TestNG.runSuitesSequentially(TestNG.java:1208)
at org.testng.TestNG.runSuitesLocally(TestNG.java:1137)
at org.testng.TestNG.runSuites(TestNG.java:1049)
at org.testng.TestNG.run(TestNG.java:1017)
at org.testng.remote.AbstractRemoteTestNG.run(AbstractRemoteTestNG.java:115)
at org.testng.remote.RemoteTestNG.initAndRun(RemoteTestNG.java:251)
at org.testng.remote.RemoteTestNG.main(RemoteTestNG.java:77)
]]>
            </full-stacktrace>
          </exception> <!-- java.lang.AssertionError -->
          <reporter-output>
          </reporter-output>
        </test-method> <!-- loginDDT -->
        <test-method status="PASS" signature="tearDown()[pri:0, instance:com.swap.TestCases.TC_LoginDDT_002@10bdf5e5]" name="tearDown" is-config="true" duration-ms="881" started-at="2021-07-17T04:00:27Z" finished-at="2021-07-17T04:00:28Z">
          <reporter-output>
          </reporter-output>
        </test-method> <!-- tearDown -->
      </class> <!-- com.swap.TestCases.TC_LoginDDT_002 -->
    </test> <!-- Test(failed) -->
  </suite> <!-- Failed suite [Suite] -->
</testng-results>
